Workbook
Name _p1: #REF!
Name _p1: #REF!
Name CURRENTYEAR: #REF!
Name CURRENTYEAR: #REF!
Name LOOKUPMTH: #REF!
Name LOOKUPMTH: #REF!
Name mi: #REF!
Name mi: #REF!
Name Month: #REF!
Name Month: #REF!
Name PRINT_AREA_MI: #REF!
Name PRINT_AREA_MI: #REF!
Name web: #REF!
Name web: #REF!

Sheet Assumptions&Calculations
A1: AGRICULTURAL AND FISHERIES MACHINERY | D1: Presets
A2: Assumptions: | B2: 2025 | D2: 2022 | E2: 2022-2021 Incremental | F2: 2021 | G2: 2021-2020 Incremental | H2: 2020 | I2: 2020-2019 Incremental | J2: 2019 | K2: 2019-2018 Incremental | L2: 2018 | M2: 2022-2020 Incremental | N2: 2025
A3: Gasoline (Php/L) | B3: 70.25 | D3: 70.7 | E3: =D3-F3 -> 15.15 | F3: =($D3*E$6)/$C$6 -> 55.55 | G3: =F3-H3 -> 10.1 | H3: =($D3*G$6)/$C$6 -> 45.45 | I3: =H3-J3 -> -5.05 | J3: =($D3*I$6)/$C$6 -> 50.5 | K3: =J3-L3 -> 2.525 | L3: =($D3*K$6)/$C$6 -> 47.975 | M3: =E3+G3 -> 25.25
A4: Diesel (Php/L) | B4: 58.3 | D4: 69.7 | E4: =D4-F4 -> 14.935714 | F4: =($D4*E$6)/$C$6 -> 54.764286 | G4: =F4-H4 -> 9.9571429 | H4: =($D4*G$6)/$C$6 -> 44.807143 | I4: =H4-J4 -> -4.9785714 | J4: =($D4*I$6)/$C$6 -> 49.785714 | K4: =J4-L4 -> 2.4892857 | L4: =($D4*K$6)/$C$6 -> 47.296429 | M4: =E4+G4 -> 24.892857
A5: Kerosene (Php/L) | B5: 72.62 | D5: 79.15 | E5: =D5-F5 -> 16.960714 | F5: =($D5*E$6)/$C$6 -> 62.189286 | G5: =F5-H5 -> 11.307143 | H5: =($D5*G$6)/$C$6 -> 50.882143 | I5: =H5-J5 -> -5.6535714 | J5: =($D5*I$6)/$C$6 -> 56.535714 | K5: =J5-L5 -> 2.8267857 | L5: =($D5*K$6)/$C$6 -> 53.708929 | M5: =E5+G5 -> 28.267857
A6: Average Price Graph | C6: 1.4 | E6: 1.1 | G6: 0.9 | I6: 1 | K6: 0.95
A7: MOPS | C7: =AVERAGE(MOPS!D150:D243) -> 158.5231 | E7: =C6*'Daily Exchange Rate'!$O8 -> 74.280402 | G7: =E6*'Daily Exchange Rate'!$O42 -> 54.200123 | I7: =G6*'Daily Exchange Rate'!$O76 -> 44.671827 | K7: =I6*'Daily Exchange Rate'!$O110 -> 51.796884 | L7: =K6*'Daily Exchange Rate'!$O144 -> 50.04248
A8: Subsidy (%) | B8: 1
A9: OPERATION | B9: MACHINERY | C9: Number of Units | D9: ASSUMPTIONS | K9: Cost Per ha | L9: TOTAL VOLUME OF FUEL | O9: TOTAL COST (Php) | R9: TOTAL COST (PHP) | S9: SUBSIDY (PHP) | T9: Land Area (ha/day) | V9: Cost Per ha | W9: Cost per ha-day
D10: Hr/ day | E10: Days/ Operation | F10: Hr/ Operation | G10: FC (L/hr) | H10: L/Operation | I10: Total Cost/ Operation Per Unit | L10: GASOLINE | M10: DIESEL | N10: KEROSENE | O10: GASOLINE | P10: DIESEL | Q10: KEROSENE | X10: Subsidy | Y10: Estimated Total Cost per ha | Z10: Percentage compared to Total Cost per ha | AA10: Percentage compared to average cost per ha-day
A11: Rice | O11: =$B$3*L11 -> 0 | P11: =$B$4*M11 -> 0 | R11: =SUM(O11:Q11) -> 0 | S11: =R11*$B$8 -> 0 | W11: =SUM(W12:W23) -> 3890.7262 | X11: =AVERAGE(W11,W24,W29,W39) -> 3547.818 | Y11: =X11*E42 -> 68065.545 | Z11: =X11/Y11 -> 0.052123552
A12: Land Preparation | B12: 4WD Tractor | C12: ='Total Inventory (Rice)'!C83 -> 24977 | D12: 8 | E12: 22 | F12: =E12*D12 -> 176 | G12: 10 | H12: =G12*F12 -> 1760 | I12: =H12*$B$4 -> 102608 | J12: =I12/E12 -> 4664 | K12: =J12/T12 -> 971.66667 | M12: =G12*F12*C12 -> 43959520 | O12: =$B$3*L12 -> 0 | P12: =$B$4*M12 -> 2562840016 | R12: =SUM(O12:Q12) -> 2562840016 | S12: =R12*$B$8 -> 2562840016 | T12: =0.6*D12 -> 4.8 | U12: =T12/D12 -> 0.6 | V12: =I12/(T12*E12)*$B$8 -> 971.66667 | W12: =AVERAGE(V12:V13) -> 680.16667 | X12: 3000 | Z12: =X12/Y11 -> 0.044075163 | AA12: =Z12/Z11 -> 0.84559016
B13: Hand Tractor | C13: ='Total Inventory (Rice)'!D83 -> 41132 | D13: 8 | E13: 22 | F13: =E13*D13 -> 176 | G13: 1 | H13: =G13*F13 -> 176 | I13: =H13*$B$4 -> 10260.8 | J13: =I13/E13 -> 466.4 | K13: =J13/T13 -> 388.66667 | M13: =G13*F13*C13 -> 7239232 | O13: =$B$3*L13 -> 0 | P13: =$B$4*M13 -> 4.2204723e+08 | R13: =SUM(O13:Q13) -> 4.2204723e+08 | S13: =R13*$B$8 -> 4.2204723e+08 | T13: =0.15*D13 -> 1.2 | U13: =T13/D13 -> 0.15 | V13: =I13/(T13*E13)*$B$8 -> 388.66667 | X13: 5000 | Z13: =X13/Y11 -> 0.073458605 | AA13: =Z13/Z11 -> 1.4093169
A14: Irrigation | B14: Engines | C14: ='Total Inventory (Rice)'!E83 -> 96776 | D14: 10 | E14: 20 | F14: =E14*D14 -> 200 | G14: 1.5 | H14: =G14*F14 -> 300 | I14: =H14*$B$4 -> 17490 | J14: =I14/E14 -> 874.5 | K14: =J14/T14 -> 874.5 | L14: =G14*F14*0.3*C14 -> 8709840 | M14: =G14*F14*0.7*C14 -> 20322960 | O14: =$B$3*L14 -> 611866260 | P14: =$B$4*M14 -> 1184828568 | R14: =SUM(O14:P14) -> 1796694828 | S14: =R14*$B$8 -> 1796694828 | T14: 1 | U14: =T14/D14 -> 0.1 | V14: =I14/(T14*E14)*$B$8 -> 874.5 | W14: =V14 -> 874.5 | X14: 7000 | Z14: =X14/Y11 -> 0.10284205 | AA14: =Z14/Z11 -> 1.9730437
A15: Transplanting | B15: Rice Transplanter (Walking-Type) | C15: ='Total Inventory (Rice)'!H83 -> 6624 | D15: 8 | E15: 22 | F15: =E15*D15 -> 176 | G15: 0.8 | H15: =G15*F15 -> 140.8 | I15: =H15*$B$4 -> 8208.64 | J15: =I15/E15 -> 373.12 | K15: =J15/T15 -> 310.93333 | L15: =G15*F15*C15 -> 932659.2 | O15: =$B$3*L15 -> 65519309 | P15: =$B$4*M15 -> 0 | R15: =SUM(O15:Q15) -> 65519309 | S15: =R15*$B$8 -> 65519309 | T15: =0.15*D15 -> 1.2 | U15: =T15/D15 -> 0.15 | V15: =I15/(T15*E15)*$B$8 -> 310.93333 | W15: =AVERAGE(V15:V17) -> 285.02222 | X15: 10000 | Z15: =X15/Y11 -> 0.14691721 | AA15: =Z15/Z11 -> 2.8186339
B16: Rice Transplanter (Ride-on-Type) | C16: ='Total Inventory (Rice)'!G83 -> 2477 | D16: 8 | E16: 22 | F16: =E16*D16 -> 176 | G16: 1 | H16: =G16*F16 -> 176 | I16: =H16*$B$4 -> 10260.8 | J16: =I16/E16 -> 466.4 | K16: =J16/T16 -> 233.2 | L16: =G16*F16*C16 -> 435952 | O16: =$B$3*L16 -> 30625628 | P16: =$B$4*M16 -> 0 | R16: =SUM(O16:Q16) -> 30625628 | S16: =R16*$B$8 -> 30625628 | T16: =0.25*D16 -> 2 | U16: =T16/D16 -> 0.25 | V16: =I16/(T16*E16)*$B$8 -> 233.2
B17: Precision Seeder and Planter | C17: ='Total Inventory (Rice)'!F83 -> 2623 | D17: 6 | E17: 22 | F17: =E17*D17 -> 132 | G17: 0.8 | H17: =G17*F17 -> 105.6 | I17: =H17*$B$4 -> 6156.48 | J17: =I17/E17 -> 279.84 | K17: =J17/T17 -> 310.93333 | L17: =G17*F17*C17 -> 276988.8 | O17: =$B$3*L17 -> 19458463 | P17: =$B$4*M17 -> 0 | R17: =SUM(O17:Q17) -> 19458463 | S17: =R17*$B$8 -> 19458463 | T17: =0.15*D17 -> 0.9 | U17: =T17/D17 -> 0.15 | V17: =I17/(T17*E17)*$B$8 -> 310.93333
A18: Crop Care | B18: Fertilizer Aplicator | C18: ='Total Inventory (Rice)'!I83 -> 10942 | D18: 8 | E18: 10 | F18: =E18*D18 -> 80 | G18: 0.8 | H18: =G18*F18 -> 64 | I18: =H18*$B$4 -> 3731.2 | J18: =I18/E18 -> 373.12 | K18: =J18/T18 -> 126.05405 | L18: =G18*F18*C18 -> 700288 | O18: =$B$3*L18 -> 49195232 | P18: =$B$4*M18 -> 0 | R18: =SUM(O18:Q18) -> 49195232 | S18: =R18*$B$8 -> 49195232 | T18: =0.37*D18 -> 2.96 | U18: =T18/D18 -> 0.37 | V18: =I18/(T18*E18)*$B$8 -> 126.05405 | W18: =V18 -> 126.05405
A19: Harvesting | B19: Mechanical Reaper | C19: ='Total Inventory (Rice)'!J83 -> 4889 | D19: 8 | E19: 15 | F19: =E19*D19 -> 120 | G19: 0.8 | H19: =G19*F19 -> 96 | I19: =H19*$B$4 -> 5596.8 | J19: =I19/E19 -> 373.12 | K19: =J19/T19 -> 126.05405 | L19: =G19*F19*C19 -> 469344 | O19: =$B$3*L19 -> 32971416 | P19: =$B$4*M19 -> 0 | R19: =SUM(O19:Q19) -> 32971416 | S19: =R19*$B$8 -> 32971416 | T19: =0.37*D19 -> 2.96 | U19: =T19/D19 -> 0.37 | V19: =I19/(T19*E19)*$B$8 -> 126.05405 | W19: =(V19+V21+V20)/2 -> 585.24928
B20: Combine Harvester | C20: ='Total Inventory (Rice)'!K83 -> 9129 | D20: 8 | E20: 40 | F20: =E20*D20 -> 320 | G20: 10 | H20: =G20*F20 -> 3200 | I20: =H20*$B$4 -> 186560 | J20: =I20/E20 -> 4664 | K20: =J20/T20 -> 932.8 | M20: =G20*F20*C20 -> 29212800 | O20: =$B$3*L20 -> 0 | P20: =$B$4*M20 -> 1703106240 | R20: =SUM(O20:Q20) -> 1703106240 | S20: =R20*$B$8 -> 1703106240 | T20: =(0.625*D20) -> 5 | U20: =T20/D20 -> 0.625 | V20: =I20/(T20*E20)*$B$8 -> 932.8
A21: Processing | B21: Thresher | C21: ='Total Inventory (Rice)'!M83 -> 14097 | D21: 8 | E21: 22 | F21: =E21*D21 -> 176 | G21: 1 | H21: =G21*F21 -> 176 | I21: =H21*$B$4 -> 10260.8 | J21: =I21/E21 -> 466.4 | K21: =J21/T21 -> 111.6445 | M21: =G21*F21*C21 -> 2481072 | O21: =$B$3*L21 -> 0 | P21: =$B$4*M21 -> 1.446465e+08 | R21: =SUM(O21:Q21) -> 1.446465e+08 | S21: =R21*$B$8 -> 1.446465e+08 | T21: =(2/3.83)*D21 -> 4.1775457 | U21: =T21/D21 -> 0.52219321 | V21: =I21/(T21*E21)*$B$8 -> 111.6445
A22: Drying | B22: Dryer | C22: ='Total Inventory (Rice)'!L83 -> 1150 | D22: 8 | E22: 30 | F22: =E22*D22 -> 240 | G22: 9 | H22: =G22*F22 -> 2160 | I22: =H22*$B$4 -> 125928 | J22: =I22/E22 -> 4197.6 | K22: =J22/T22 -> 1004.8005 | N22: =G22*F22*C22 -> 2484000 | O22: =$B$3*L22 -> 0 | Q22: =$B$4*N22 -> 144817200 | R22: =SUM(O22:Q22) -> 144817200 | S22: =R22*$B$8 -> 144817200 | T22: =(2/3.83)*D22 -> 4.1775457 | U22: =T22/D22 -> 0.52219321 | V22: =I22/(T22*E22)*$B$8 -> 1004.8005 | W22: =V22 -> 1004.8005
A23: Hauling/ Transport | B23: Truck/ Forklift | C23: ='Total Inventory (Rice)'!N83 -> 5 | D23: 8 | E23: 15 | F23: =E23*D23 -> 120 | G23: 3 | H23: =G23*F23 -> 360 | I23: =H23*$B$4 -> 20988 | J23: =I23/E23 -> 1399.2 | K23: =J23/T23 -> 334.9335 | M23: =G23*F23*C23 -> 1800 | O23: =$B$3*L23 -> 0 | P23: =$B$4*M23 -> 104940 | R23: =SUM(O23:Q23) -> 104940 | S23: =R23*$B$8 -> 104940 | T23: =(2/3.83)*D23 -> 4.1775457 | U23: =T23/D23 -> 0.52219321 | V23: =I23/(T23*E23)*$B$8 -> 334.9335 | W23: =V23 -> 334.9335
A24: Corn | O24: =$B$3*L24 -> 0 | P24: =$B$4*M24 -> 0 | R24: =SUM(O24:Q24) -> 0 | S24: =R24*$B$8 -> 0 | W24: =SUM(W25:W28) -> 4449.0673
A25: Land Preparation | B25: 4WD Tractor | C25: ='Total Inventory (Corn)'!C83 -> 13043 | D25: 8 | E25: 30 | F25: =E25*D25 -> 240 | G25: 20 | H25: =G25*F25 -> 4800 | I25: =H25*$B$4 -> 279840 | J25: =I25/E25 -> 9328 | K25: =J25/T25 -> 1943.3333 | M25: =G25*F25*C25 -> 62606400 | O25: =$B$3*L25 -> 0 | P25: =$B$4*M25 -> 3649953120 | R25: =SUM(O25:Q25) -> 3649953120 | S25: =R25*$B$8 -> 3649953120 | T25: =0.6*D12 -> 4.8 | U25: =T25/D25 -> 0.6 | V25: =I25/(T25*E25)*$B$8 -> 1943.3333 | W25: =V25 -> 1943.3333
A26: Harvesting | B26: Combine Harvesters | C26: ='Total Inventory (Corn)'!D83 -> 2164 | D26: 8 | E26: 22 | F26: =E26*D26 -> 176 | G26: 10 | H26: =G26*F26 -> 1760 | I26: =H26*$B$4 -> 102608 | J26: =I26/E26 -> 4664 | K26: =J26/T26 -> 1166 | M26: =G26*F26*C26 -> 3808640 | O26: =$B$3*L26 -> 0 | P26: =$B$4*M26 -> 222043712 | R26: =SUM(O26:Q26) -> 222043712 | S26: =R26*$B$8 -> 222043712 | T26: =(0.5*D26) -> 4 | U26: =T26/D26 -> 0.5 | V26: =I26/(T26*E26)*$B$8 -> 1166 | W26: =V26 -> 1166
A27: Drying | B27: Dryer | C27: ='Total Inventory (Corn)'!E83 -> 2901 | D27: 8 | E27: 30 | F27: =E27*D27 -> 240 | G27: 9 | H27: =G27*F27 -> 2160 | I27: =H27*$B$4 -> 125928 | J27: =I27/E27 -> 4197.6 | K27: =J27/T27 -> 1004.8005 | M27: =G27*F27*C27 -> 6266160 | O27: =$B$3*L27 -> 0 | P27: =$B$4*M27 -> 365317128 | R27: =SUM(O27:Q27) -> 365317128 | S27: =R27*$B$8 -> 365317128 | T27: =(2/3.83)*D27 -> 4.1775457 | U27: =T27/D27 -> 0.52219321 | V27: =I27/(T27*E27)*$B$8 -> 1004.8005 | W27: =V27 -> 1004.8005
A28: Processing | B28: Pre Processing and Size Reduction Machinery | C28: ='Total Inventory (Corn)'!F83 -> 21007 | D28: 8 | E28: 22 | F28: =E28*D28 -> 176 | G28: 3 | H28: =G28*F28 -> 528 | I28: =H28*$B$4 -> 30782.4 | J28: =I28/E28 -> 1399.2 | K28: =J28/T28 -> 334.9335 | M28: =G28*F28*C28 -> 11091696 | O28: =$B$3*L28 -> 0 | P28: =$B$4*M28 -> 6.4664588e+08 | R28: =SUM(O28:Q28) -> 6.4664588e+08 | S28: =R28*$B$8 -> 6.4664588e+08 | T28: =(2/3.83)*D28 -> 4.1775457 | U28: =T28/D28 -> 0.52219321 | V28: =I28/(T28*E28)*$B$8 -> 334.9335 | W28: =V28 -> 334.9335
A29: HVC | O29: =$B$3*L29 -> 0 | P29: =$B$4*M29 -> 0 | R29: =SUM(O29:Q29) -> 0 | S29: =R29*$B$8 -> 0 | W29: =SUM(W30:W38) -> 3559.584
A30: Land Preparation | B30: 4WD Tractor | C30: ='Total Inventory (HVC)'!C85 -> 23187 | D30: 6 | E30: 10 | F30: =E30*D30 -> 60 | G30: 15 | H30: =G30*F30 -> 900 | I30: =H30*$B$4 -> 52470 | J30: =I30/E30 -> 5247 | K30: =J30/T30 -> 1093.125 | M30: =G30*F30*C30 -> 20868300 | O30: =$B$3*L30 -> 0 | P30: =$B$4*M30 -> 1216621890 | R30: =SUM(O30:Q30) -> 1216621890 | S30: =R30*$B$8 -> 1216621890 | T30: =0.6*D21 -> 4.8 | U30: =T30/D30 -> 0.8 | V30: =I30/(T30*E30)*$B$8 -> 1093.125 | W30: =AVERAGE(V30:V31) -> 740.89583
B31: Hand Tractor | D31: 6 | E31: 10 | F31: =E31*D31 -> 60 | G31: 1 | H31: =G31*F31 -> 60 | I31: =H31*$B$4 -> 3498 | J31: =I31/E31 -> 349.8 | K31: =J31/T31 -> 388.66667 | M31: =G31*F31*C31 -> 0 | O31: =$B$3*L31 -> 0 | P31: =$B$4*M31 -> 0 | R31: =SUM(O31:Q31) -> 0 | S31: =R31*$B$8 -> 0 | T31: =0.15*D31 -> 0.9 | U31: =T31/D31 -> 0.15 | V31: =I31/(T31*E31)*$B$8 -> 388.66667
A32: Planter | B32: Precision Seeder and Planter | C32: ='Total Inventory (HVC)'!E85 -> 5 | D32: 6 | E32: 22 | F32: =E32*D32 -> 132 | G32: 0.8 | H32: =G32*F32 -> 105.6 | I32: =H32*$B$4 -> 6156.48 | J32: =I32/E32 -> 279.84 | K32: =J32/T32 -> 310.93333 | L32: =G32*F32*C32 -> 528 | O32: =$B$3*L32 -> 37092 | P32: =$B$4*M32 -> 0 | R32: =SUM(O32:Q32) -> 37092 | S32: =R32*$B$8 -> 37092 | T32: =0.15*D32 -> 0.9 | U32: =T32/D32 -> 0.15 | V32: =I32/(T32*E32)*$B$8 -> 310.93333 | W32: =V32 -> 310.93333
A33: Crop Care | B33: Fertilizer Aplicator | C33: ='Total Inventory (HVC)'!F85 -> 49320 | D33: 8 | E33: 10 | F33: =E33*D33 -> 80 | G33: 0.8 | H33: =G33*F33 -> 64 | I33: =H33*$B$4 -> 3731.2 | J33: =I33/E33 -> 373.12 | K33: =J33/T33 -> 126.05405 | L33: =G33*F33*C33 -> 3156480 | O33: =$B$3*L33 -> 221742720 | P33: =$B$4*M33 -> 0 | R33: =SUM(O33:Q33) -> 221742720 | S33: =R33*$B$8 -> 221742720 | T33: =0.37*D33 -> 2.96 | U33: =T33/D33 -> 0.37 | V33: =I33/(T33*E33)*$B$8 -> 126.05405 | W33: =V33 -> 126.05405
A34: Harvesting and Processing | B34: Harvesters | C34: ='Total Inventory (HVC)'!G85 -> 15 | D34: 6 | E34: 15 | F34: =E34*D34 -> 90 | G34: 10 | H34: =G34*F34 -> 900 | I34: =H34*$B$4 -> 52470 | J34: =I34/E34 -> 3498 | K34: =J34/T34 -> 1408.2126 | M34: =G34*F34*C34 -> 13500 | O34: =$B$3*L34 -> 0 | P34: =$B$4*M34 -> 787050 | R34: =SUM(O34:Q34) -> 787050 | S34: =R34*$B$8 -> 787050 | T34: =(0.414*D34) -> 2.484 | U34: =T34/D34 -> 0.414 | V34: =I34/(T34*E34)*$B$8 -> 1408.2126
A35: Processing | B35: Processing and Size Reduction Machinery | C35: ='Total Inventory (HVC)'!H85 -> 26185 | D35: 6 | E35: 15 | F35: =E35*D35 -> 90 | G35: 1.5 | H35: =G35*F35 -> 135 | I35: =H35*$B$4 -> 7870.5 | J35: =I35/E35 -> 524.7 | K35: =J35/T35 -> 167.46675 | M35: =G35*F35*C35 -> 3534975 | O35: =$B$3*L35 -> 0 | P35: =$B$4*M35 -> 2.0608904e+08 | R35: =SUM(O35:Q35) -> 2.0608904e+08 | S35: =R35*$B$8 -> 2.0608904e+08 | T35: =(2/3.83)*D35 -> 3.1331593 | U35: =T35/D35 -> 0.52219321 | V35: =I35/(T35*E35)*$B$8 -> 167.46675 | W35: =V35 -> 167.46675
A36: Drying | B36: Thermal Processing | C36: ='Total Inventory (HVC)'!I85 -> 2625 | D36: 8 | E36: 30 | F36: =E36*D36 -> 240 | G36: 9 | H36: =G36*F36 -> 2160 | I36: =H36*$B$4 -> 125928 | J36: =I36/E36 -> 4197.6 | K36: =J36/T36 -> 1004.8005 | N36: =G36*F36*C36 -> 5670000 | O36: =$B$3*L36 -> 0 | P36: =$B$4*M36 -> 0 | Q36: =$B$4*N36 -> 330561000 | R36: =SUM(O36:Q36) -> 330561000 | S36: =R36*$B$8 -> 330561000 | T36: =(2/3.83)*D36 -> 4.1775457 | U36: =T36/D36 -> 0.52219321 | V36: =I36/(T36*E36)*$B$8 -> 1004.8005 | W36: =V36 -> 1004.8005
A37: Irrigation | B37: Engines | C37: ='Total Inventory (HVC)'!D85 -> 325 | D37: 10 | E37: 10 | F37: =E37*D37 -> 100 | G37: 1.5 | H37: =G37*F37 -> 150 | I37: =H37*$B$4 -> 8745 | J37: =I37/E37 -> 874.5 | K37: =J37/T37 -> 874.5 | L37: =G37*F37*0.3*C37 -> 14625 | M37: =G37*F37*0.7*C37 -> 34125 | O37: =$B$3*L37 -> 1027406.2 | P37: =$B$4*M37 -> 1989487.5 | R37: =SUM(O37:P37) -> 3016893.8 | S37: =R37*$B$8 -> 3016893.8 | T37: 1 | U37: =T37/D37 -> 0.1 | V37: =I37/(T37*E37)*$B$8 -> 874.5 | W37: =V37 -> 874.5
A38: Hauling/ Transport | B38: Truck/ Forklift | C38: ='Total Inventory (HVC)'!J85 -> 993 | D38: 8 | E38: 15 | F38: =E38*D38 -> 120 | G38: 3 | H38: =G38*F38 -> 360 | I38: =H38*$B$4 -> 20988 | J38: =I38/E38 -> 1399.2 | K38: =J38/T38 -> 334.9335 | M38: =G38*F38*C38 -> 357480 | O38: =$B$3*L38 -> 0 | P38: =$B$4*M38 -> 20841084 | R38: =SUM(O38:Q38) -> 20841084 | S38: =R38*$B$8 -> 20841084 | T38: =(2/3.83)*D38 -> 4.1775457 | U38: =T38/D38 -> 0.52219321 | V38: =I38/(T38*E38)*$B$8 -> 334.9335 | W38: =V38 -> 334.9335
A39: Sugar | W39: =SUM(W40:W41) -> 2291.8945
A40: Land Preparation | B40: 4WD Tractor | C40: 2911 | D40: 6 | E40: 10 | F40: =E40*D40 -> 60 | G40: 36.41 | H40: =BreakDown!B37 -> 80 | I40: =H40*$B$4 -> 4664 | J40: =I40/E40 -> 466.4 | K40: =J40/T40 -> 62.186667 | M40: =G40*F40*C40 -> 6359370.6 | O40: =$B$3*L40 -> 0 | P40: =$B$4*M40 -> 3.7075131e+08 | R40: =SUM(O40:Q40) -> 3.7075131e+08 | S40: =R40*$B$8 -> 3.7075131e+08 | T40: =1.5*5 -> 7.5 | U40: =T40/D40 -> 1.25 | V40: =I40/(T40*E40)*$B$8 -> 62.186667 | W40: =AVERAGE(V40:V41) -> 784.69371
...

Sheet Summary
A1: REGIONAL FUEL REQUIREMENT PER MONTH | O1: =SUM(O20,O40,O60,O80,O101,O121) -> 1.1048985e+11 | P1: =SUM(P20,P40,P60,P80) -> 1.3201677e+10 | Q1: =O121+O101 -> 7.6619716e+10
A2: RICE | B2: January | C2: February | D2: March | E2: April | F2: May | G2: June | H2: July | I2: August | J2: September | K2: October | L2: November | M2: December | N2: Total Fuel (L) Per Region | O2: Cost (Php) Per Region @ average fuel cost | P2: Cost (Php) Per Region @ incremental cost
A3: CAR | B3: =SUM('Total Fuel per Operation (Rice)'!S$4:S$9) -> 64895.8 | C3: =SUM('Total Fuel per Operation (Rice)'!T$4:T$9) -> 68623 | D3: =SUM('Total Fuel per Operation (Rice)'!U$4:U$9) -> 92490 | E3: =SUM('Total Fuel per Operation (Rice)'!V$4:V$9) -> 111792 | F3: =SUM('Total Fuel per Operation (Rice)'!W$4:W$9) -> 251946 | G3: =SUM('Total Fuel per Operation (Rice)'!X$4:X$9) -> 178107 | H3: =SUM('Total Fuel per Operation (Rice)'!Y$4:Y$9) -> 249908.8 | I3: =SUM('Total Fuel per Operation (Rice)'!Z$4:Z$9) -> 197437 | ... M3: =SUM('Total Fuel per Operation (Rice)'!AD$4:AD$9) -> 279176 | N3: =SUM(B3:M3) -> 2007985.6 | O3: =$N3*AVERAGE('Assumptions&Calculations'!$B$3:$B$5) -> 1.3464882e+08 | P3: =$N3*AVERAGE('Assumptions&Calculations'!$M$3:$M$5) -> 52482528
A4: Region I | B4: =SUM('Total Fuel per Operation (Rice)'!S$10:S$13) -> 4163424 | C4: =SUM('Total Fuel per Operation (Rice)'!T$10:T$13) -> 160688 | D4: =SUM('Total Fuel per Operation (Rice)'!U$10:U$13) -> 10254712 | E4: =SUM('Total Fuel per Operation (Rice)'!V$10:V$13) -> 1026727.8 | F4: =SUM('Total Fuel per Operation (Rice)'!W$10:W$13) -> 1206345 | G4: =SUM('Total Fuel per Operation (Rice)'!X$10:X$13) -> 4163424 | H4: =SUM('Total Fuel per Operation (Rice)'!Y$10:Y$13) -> 160688 | I4: =SUM('Total Fuel per Operation (Rice)'!Z$10:Z$13) -> 0 | ... M4: =SUM('Total Fuel per Operation (Rice)'!AD$10:AD$13) -> 1206345 | N4: =SUM(B4:M4) -> 33623794 | O4: =$N4*AVERAGE('Assumptions&Calculations'!$B$3:$B$5) -> 2.2546995e+09 | P4: =$N4*AVERAGE('Assumptions&Calculations'!$M$3:$M$5) -> 8.7882189e+08
A5: Region II | B5: =SUM('Total Fuel per Operation (Rice)'!S$14:S$18) -> 3389210.4 | C5: =SUM('Total Fuel per Operation (Rice)'!T$14:T$18) -> 1644659 | D5: =SUM('Total Fuel per Operation (Rice)'!U$14:U$18) -> 783584 | E5: =SUM('Total Fuel per Operation (Rice)'!V$14:V$18) -> 4224 | F5: =SUM('Total Fuel per Operation (Rice)'!W$14:W$18) -> 9573640 | G5: =SUM('Total Fuel per Operation (Rice)'!X$14:X$18) -> 9526796.6 | H5: =SUM('Total Fuel per Operation (Rice)'!Y$14:Y$18) -> 2719410.6 | I5: =SUM('Total Fuel per Operation (Rice)'!Z$14:Z$18) -> 3810152 | ... M5: =SUM('Total Fuel per Operation (Rice)'!AD$14:AD$18) -> 4521644.4 | N5: =SUM(B5:M5) -> 54953507 | O5: =$N5*AVERAGE('Assumptions&Calculations'!$B$3:$B$5) -> 3.684999e+09 | P5: =$N5*AVERAGE('Assumptions&Calculations'!$M$3:$M$5) -> 1.4363146e+09
A6: Region III | B6: =SUM('Total Fuel per Operation (Rice)'!S$19:S$25) -> 2307900 | C6: =SUM('Total Fuel per Operation (Rice)'!T$19:T$25) -> 4154144 | D6: =SUM('Total Fuel per Operation (Rice)'!U$19:U$25) -> 705648 | E6: =SUM('Total Fuel per Operation (Rice)'!V$19:V$25) -> 0 | F6: =SUM('Total Fuel per Operation (Rice)'!W$19:W$25) -> 0 | G6: =SUM('Total Fuel per Operation (Rice)'!X$19:X$25) -> 7325360 | H6: =SUM('Total Fuel per Operation (Rice)'!Y$19:Y$25) -> 1794685.6 | I6: =SUM('Total Fuel per Operation (Rice)'!Z$19:Z$25) -> 2307900 | ... M6: =SUM('Total Fuel per Operation (Rice)'!AD$19:AD$25) -> 2411155.6 | N6: =SUM(B6:M6) -> 33191945 | O6: =$N6*AVERAGE('Assumptions&Calculations'!$B$3:$B$5) -> 2.2257412e+09 | P6: =$N6*AVERAGE('Assumptions&Calculations'!$M$3:$M$5) -> 8.6753471e+08
A7: CALABARZON | B7: =SUM('Total Fuel per Operation (Rice)'!S$26:S$30) -> 670858 | C7: =SUM('Total Fuel per Operation (Rice)'!T$26:T$30) -> 1110176 | D7: =SUM('Total Fuel per Operation (Rice)'!U$26:U$30) -> 158272 | E7: =SUM('Total Fuel per Operation (Rice)'!V$26:V$30) -> 0 | F7: =SUM('Total Fuel per Operation (Rice)'!W$26:W$30) -> 0 | G7: =SUM('Total Fuel per Operation (Rice)'!X$26:X$30) -> 1281496 | H7: =SUM('Total Fuel per Operation (Rice)'!Y$26:Y$30) -> 1790075.8 | I7: =SUM('Total Fuel per Operation (Rice)'!Z$26:Z$30) -> 529449.4 | ... M7: =SUM('Total Fuel per Operation (Rice)'!AD$26:AD$30) -> 529449.4 | N7: =SUM(B7:M7) -> 11080654 | O7: =$N7*AVERAGE('Assumptions&Calculations'!$B$3:$B$5) -> 7.4303175e+08 | P7: =$N7*AVERAGE('Assumptions&Calculations'!$M$3:$M$5) -> 2.8961401e+08
A8: MIMAROPA | B8: =SUM('Total Fuel per Operation (Rice)'!S$31:S$35) -> 1159824 | C8: =SUM('Total Fuel per Operation (Rice)'!T$31:T$35) -> 114032 | D8: =SUM('Total Fuel per Operation (Rice)'!U$31:U$35) -> 0 | E8: =SUM('Total Fuel per Operation (Rice)'!V$31:V$35) -> 1159136 | F8: =SUM('Total Fuel per Operation (Rice)'!W$31:W$35) -> 1922404.4 | G8: =SUM('Total Fuel per Operation (Rice)'!X$31:X$35) -> 384279.2 | H8: =SUM('Total Fuel per Operation (Rice)'!Y$31:Y$35) -> 1314270 | I8: =SUM('Total Fuel per Operation (Rice)'!Z$31:Z$35) -> 484720 | ... M8: =SUM('Total Fuel per Operation (Rice)'!AD$31:AD$35) -> 625705 | N8: =SUM(B8:M8) -> 10699891 | O8: =$N8*AVERAGE('Assumptions&Calculations'!$B$3:$B$5) -> 7.1749904e+08 | P8: =$N8*AVERAGE('Assumptions&Calculations'!$M$3:$M$5) -> 2.7966204e+08
A9: Region V | B9: =SUM('Total Fuel per Operation (Rice)'!S$36:S$41) -> 580284.6 | C9: =SUM('Total Fuel per Operation (Rice)'!T$36:T$41) -> 1777156.6 | D9: =SUM('Total Fuel per Operation (Rice)'!U$36:U$41) -> 1033653 | E9: =SUM('Total Fuel per Operation (Rice)'!V$36:V$41) -> 530326.2 | F9: =SUM('Total Fuel per Operation (Rice)'!W$36:W$41) -> 202929 | G9: =SUM('Total Fuel per Operation (Rice)'!X$36:X$41) -> 879288 | H9: =SUM('Total Fuel per Operation (Rice)'!Y$36:Y$41) -> 2038654.2 | I9: =SUM('Total Fuel per Operation (Rice)'!Z$36:Z$41) -> 334124.4 | ... M9: =SUM('Total Fuel per Operation (Rice)'!AD$36:AD$41) -> 500603.4 | N9: =SUM(B9:M9) -> 13271970 | O9: =$N9*AVERAGE('Assumptions&Calculations'!$B$3:$B$5) -> 8.8997404e+08 | P9: =$N9*AVERAGE('Assumptions&Calculations'!$M$3:$M$5) -> 3.4688821e+08
A10: Region VI | B10: =SUM('Total Fuel per Operation (Rice)'!S$42:S$46) -> 838493 | C10: =SUM('Total Fuel per Operation (Rice)'!T$42:T$46) -> 1241024 | D10: =SUM('Total Fuel per Operation (Rice)'!U$42:U$46) -> 212672 | E10: =SUM('Total Fuel per Operation (Rice)'!V$42:V$46) -> 0 | F10: =SUM('Total Fuel per Operation (Rice)'!W$42:W$46) -> 1544632 | G10: =SUM('Total Fuel per Operation (Rice)'!X$42:X$46) -> 257725.4 | H10: =SUM('Total Fuel per Operation (Rice)'!Y$42:Y$46) -> 838493 | I10: =SUM('Total Fuel per Operation (Rice)'!Z$42:Z$46) -> 1241024 | ... M10: =SUM('Total Fuel per Operation (Rice)'!AD$42:AD$46) -> 257725.4 | N10: =SUM(B10:M10) -> 8189092.8 | O10: =$N10*AVERAGE('Assumptions&Calculations'!$B$3:$B$5) -> 5.4913327e+08 | P10: =$N10*AVERAGE('Assumptions&Calculations'!$M$3:$M$5) -> 2.1403754e+08
A11: NIR | B11: =SUM('Total Fuel per Operation (Rice)'!S$47:S$49) -> 123382 | C11: =SUM('Total Fuel per Operation (Rice)'!T$47:T$49) -> 177024 | D11: =SUM('Total Fuel per Operation (Rice)'!U$47:U$49) -> 27456 | E11: =SUM('Total Fuel per Operation (Rice)'!V$47:V$49) -> 0 | F11: =SUM('Total Fuel per Operation (Rice)'!W$47:W$49) -> 644048 | G11: =SUM('Total Fuel per Operation (Rice)'!X$47:X$49) -> 55506.4 | H11: =SUM('Total Fuel per Operation (Rice)'!Y$47:Y$49) -> 75652 | I11: =SUM('Total Fuel per Operation (Rice)'!Z$47:Z$49) -> 244640 | ... M11: =SUM('Total Fuel per Operation (Rice)'!AD$47:AD$49) -> 100469.2 | N11: =SUM(B11:M11) -> 2220524.8 | O11: =$N11*AVERAGE('Assumptions&Calculations'!$B$3:$B$5) -> 1.4890099e+08 | P11: =$N11*AVERAGE('Assumptions&Calculations'!$M$3:$M$5) -> 58037645
A12: Region VII | B12: =SUM('Total Fuel per Operation (Rice)'!S$50:S$51) -> 0 | C12: =SUM('Total Fuel per Operation (Rice)'!T$50:T$51) -> 0 | D12: =SUM('Total Fuel per Operation (Rice)'!U$50:U$51) -> 0 | E12: =SUM('Total Fuel per Operation (Rice)'!V$50:V$51) -> 949928 | F12: =SUM('Total Fuel per Operation (Rice)'!W$50:W$51) -> 78517.8 | G12: =SUM('Total Fuel per Operation (Rice)'!X$50:X$51) -> 59955 | H12: =SUM('Total Fuel per Operation (Rice)'!Y$50:Y$51) -> 100768 | I12: =SUM('Total Fuel per Operation (Rice)'!Z$50:Z$51) -> 1220792 | ... M12: =SUM('Total Fuel per Operation (Rice)'!AD$50:AD$51) -> 270864 | N12: =SUM(B12:M12) -> 2920065.6 | O12: =$N12*AVERAGE('Assumptions&Calculations'!$B$3:$B$5) -> 1.9580987e+08 | P12: =$N12*AVERAGE('Assumptions&Calculations'!$M$3:$M$5) -> 76321476
A13: Region VIII | B13: =SUM('Total Fuel per Operation (Rice)'!S$52:S$57) -> 336891.6 | C13: =SUM('Total Fuel per Operation (Rice)'!T$52:T$57) -> 321509 | D13: =SUM('Total Fuel per Operation (Rice)'!U$52:U$57) -> 716912 | E13: =SUM('Total Fuel per Operation (Rice)'!V$52:V$57) -> 371632 | F13: =SUM('Total Fuel per Operation (Rice)'!W$52:W$57) -> 647048 | G13: =SUM('Total Fuel per Operation (Rice)'!X$52:X$57) -> 1205885.8 | H13: =SUM('Total Fuel per Operation (Rice)'!Y$52:Y$57) -> 336891.6 | I13: =SUM('Total Fuel per Operation (Rice)'!Z$52:Z$57) -> 321509 | ... M13: =SUM('Total Fuel per Operation (Rice)'!AD$52:AD$57) -> 1205885.8 | N13: =SUM(B13:M13) -> 7199756.8 | O13: =$N13*AVERAGE('Assumptions&Calculations'!$B$3:$B$5) -> 4.8279169e+08 | P13: =$N13*AVERAGE('Assumptions&Calculations'!$M$3:$M$5) -> 1.8817936e+08
A14: Region IX | B14: =SUM('Total Fuel per Operation (Rice)'!S$58:S$60) -> 432822 | C14: =SUM('Total Fuel per Operation (Rice)'!T$58:T$60) -> 493552 | D14: =SUM('Total Fuel per Operation (Rice)'!U$58:U$60) -> 87648 | E14: =SUM('Total Fuel per Operation (Rice)'!V$58:V$60) -> 0 | F14: =SUM('Total Fuel per Operation (Rice)'!W$58:W$60) -> 1148736 | G14: =SUM('Total Fuel per Operation (Rice)'!X$58:X$60) -> 127211.6 | H14: =SUM('Total Fuel per Operation (Rice)'!Y$58:Y$60) -> 77910 | I14: =SUM('Total Fuel per Operation (Rice)'!Z$58:Z$60) -> 778368 | ... M14: =SUM('Total Fuel per Operation (Rice)'!AD$58:AD$60) -> 93963.6 | N14: =SUM(B14:M14) -> 4640419.2 | O14: =$N14*AVERAGE('Assumptions&Calculations'!$B$3:$B$5) -> 3.1117104e+08 | P14: =$N14*AVERAGE('Assumptions&Calculations'!$M$3:$M$5) -> 1.2128619e+08
A15: Region X | B15: =SUM('Total Fuel per Operation (Rice)'!S$61:S$65) -> 1117885 | C15: =SUM('Total Fuel per Operation (Rice)'!T$61:T$65) -> 1319856 | D15: =SUM('Total Fuel per Operation (Rice)'!U$61:U$65) -> 77808 | E15: =SUM('Total Fuel per Operation (Rice)'!V$61:V$65) -> 0 | F15: =SUM('Total Fuel per Operation (Rice)'!W$61:W$65) -> 4431552 | G15: =SUM('Total Fuel per Operation (Rice)'!X$61:X$65) -> 465158.4 | H15: =SUM('Total Fuel per Operation (Rice)'!Y$61:Y$65) -> 364560 | I15: =SUM('Total Fuel per Operation (Rice)'!Z$61:Z$65) -> 2089216 | ... M15: =SUM('Total Fuel per Operation (Rice)'!AD$61:AD$65) -> 381981.2 | N15: =SUM(B15:M15) -> 15273709 | O15: =$N15*AVERAGE('Assumptions&Calculations'!$B$3:$B$5) -> 1.024204e+09 | P15: =$N15*AVERAGE('Assumptions&Calculations'!$M$3:$M$5) -> 3.9920747e+08
A16: Region XI | B16: =SUM('Total Fuel per Operation (Rice)'!S$66:S$70) -> 291183 | C16: =SUM('Total Fuel per Operation (Rice)'!T$66:T$70) -> 1008816 | D16: =SUM('Total Fuel per Operation (Rice)'!U$66:U$70) -> 101952 | E16: =SUM('Total Fuel per Operation (Rice)'!V$66:V$70) -> 1250440 | F16: =SUM('Total Fuel per Operation (Rice)'!W$66:W$70) -> 543789 | G16: =SUM('Total Fuel per Operation (Rice)'!X$66:X$70) -> 165475 | H16: =SUM('Total Fuel per Operation (Rice)'!Y$66:Y$70) -> 1003884 | I16: =SUM('Total Fuel per Operation (Rice)'!Z$66:Z$70) -> 262016 | ... M16: =SUM('Total Fuel per Operation (Rice)'!AD$66:AD$70) -> 184469 | N16: =SUM(B16:M16) -> 6991960 | O16: =$N16*AVERAGE('Assumptions&Calculations'!$B$3:$B$5) -> 4.6885753e+08 | P16: =$N16*AVERAGE('Assumptions&Calculations'!$M$3:$M$5) -> 1.8274819e+08
A17: Region XII | B17: =SUM('Total Fuel per Operation (Rice)'!S$71:S$74) -> 220872 | C17: =SUM('Total Fuel per Operation (Rice)'!T$71:T$74) -> 0 | D17: =SUM('Total Fuel per Operation (Rice)'!U$71:U$74) -> 0 | E17: =SUM('Total Fuel per Operation (Rice)'!V$71:V$74) -> 3871088 | F17: =SUM('Total Fuel per Operation (Rice)'!W$71:W$74) -> 484437.6 | G17: =SUM('Total Fuel per Operation (Rice)'!X$71:X$74) -> 665268 | H17: =SUM('Total Fuel per Operation (Rice)'!Y$71:Y$74) -> 2650304 | I17: =SUM('Total Fuel per Operation (Rice)'!Z$71:Z$74) -> 220872 | ... M17: =SUM('Total Fuel per Operation (Rice)'!AD$71:AD$74) -> 2650304 | N17: =SUM(B17:M17) -> 15783939 | O17: =$N17*AVERAGE('Assumptions&Calculations'!$B$3:$B$5) -> 1.0584183e+09 | P17: =$N17*AVERAGE('Assumptions&Calculations'!$M$3:$M$5) -> 4.1254332e+08
A18: Region XIII | B18: =SUM('Total Fuel per Operation (Rice)'!S$75:S$79) -> 1670895 | C18: =SUM('Total Fuel per Operation (Rice)'!T$75:T$79) -> 1597200 | D18: =SUM('Total Fuel per Operation (Rice)'!U$75:U$79) -> 146336 | E18: =SUM('Total Fuel per Operation (Rice)'!V$75:V$79) -> 0 | F18: =SUM('Total Fuel per Operation (Rice)'!W$75:W$79) -> 1020800 | G18: =SUM('Total Fuel per Operation (Rice)'!X$75:X$79) -> 1619582 | H18: =SUM('Total Fuel per Operation (Rice)'!Y$75:Y$79) -> 520883.4 | I18: =SUM('Total Fuel per Operation (Rice)'!Z$75:Z$79) -> 1501385 | ... M18: =SUM('Total Fuel per Operation (Rice)'!AD$75:AD$79) -> 511922.6 | N18: =SUM(B18:M18) -> 15741677 | O18: =$N18*AVERAGE('Assumptions&Calculations'!$B$3:$B$5) -> 1.0555844e+09 | P18: =$N18*AVERAGE('Assumptions&Calculations'!$M$3:$M$5) -> 4.1143871e+08
A19: BARMM | B19: =SUM('Total Fuel per Operation (Rice)'!S$80:S$82) -> 0 | C19: =SUM('Total Fuel per Operation (Rice)'!T$80:T$82) -> 0 | D19: =SUM('Total Fuel per Operation (Rice)'!U$80:U$82) -> 0 | E19: =SUM('Total Fuel per Operation (Rice)'!V$80:V$82) -> 0 | F19: =SUM('Total Fuel per Operation (Rice)'!W$80:W$82) -> 77440 | G19: =SUM('Total Fuel per Operation (Rice)'!X$80:X$82) -> 0 | H19: =SUM('Total Fuel per Operation (Rice)'!Y$80:Y$82) -> 0 | I19: =SUM('Total Fuel per Operation (Rice)'!Z$80:Z$82) -> 77440 | ... M19: =SUM('Total Fuel per Operation (Rice)'!AD$80:AD$82) -> 2640 | N19: =SUM(B19:M19) -> 157520 | O19: =$N19*AVERAGE('Assumptions&Calculations'!$B$3:$B$5) -> 10562766 | P19: =$N19*AVERAGE('Assumptions&Calculations'!$M$3:$M$5) -> 4117085.2
A20: Total per Month | B20: =SUM(B3:B19) -> 17368820 | C20: =SUM(C3:C19) -> 15188460 | D20: =SUM(D3:D19) -> 14399143 | E20: =SUM(E3:E19) -> 9275294 | F20: =SUM(F3:F19) -> 23778265 | G20: =SUM(G3:G19) -> 28360518 | H20: =SUM(H3:H19) -> 16037039 | I20: =SUM(I3:I19) -> 15621045 | ... N20: =SUM(N3:N19) -> 237948411 | O20: =$N20*AVERAGE('Assumptions&Calculations'!$B$3:$B$5) -> 1.5956027e+10 | P20: =$N20*AVERAGE('Assumptions&Calculations'!$M$3:$M$5) -> 6.219235e+09
A22: CORN | B22: January | C22: February | D22: March | E22: April | F22: May | G22: June | H22: July | I22: August | J22: September | K22: October | L22: November | M22: December | N22: Total Fuel (L) Per Region | O22: Cost (Php) Per Region @ average fuel cost | P22: Cost (Php) Per Region @ incremental cost
A23: CAR | B23: =SUM('Total Fuel per Operation (Corn)'!H$4:H$9) -> 626912 | C23: =SUM('Total Fuel per Operation (Corn)'!I$4:I$9) -> 1312432 | D23: =SUM('Total Fuel per Operation (Corn)'!J$4:J$9) -> 0 | E23: =SUM('Total Fuel per Operation (Corn)'!K$4:K$9) -> 1315200 | F23: =SUM('Total Fuel per Operation (Corn)'!L$4:L$9) -> 404272 | G23: =SUM('Total Fuel per Operation (Corn)'!M$4:M$9) -> 0 | H23: =SUM('Total Fuel per Operation (Corn)'!N$4:N$9) -> 1160672 | I23: =SUM('Total Fuel per Operation (Corn)'!O$4:O$9) -> 0 | ... M23: =SUM('Total Fuel per Operation (Corn)'!S$4:S$9) -> 0 | N23: =SUM(B23:M23) -> 6509088 | O23: =$N23*AVERAGE('Assumptions&Calculations'!$B$3:$B$5) -> 4.3647774e+08 | P23: =$N23*AVERAGE('Assumptions&Calculations'!$M$3:$M$5) -> 1.7012741e+08
A24: Region I | B24: =SUM('Total Fuel per Operation (Corn)'!H$10:H$13) -> 0 | C24: =SUM('Total Fuel per Operation (Corn)'!I$10:I$13) -> 12398400 | D24: =SUM('Total Fuel per Operation (Corn)'!J$10:J$13) -> 0 | E24: =SUM('Total Fuel per Operation (Corn)'!K$10:K$13) -> 0 | F24: =SUM('Total Fuel per Operation (Corn)'!L$10:L$13) -> 1089760 | G24: =SUM('Total Fuel per Operation (Corn)'!M$10:M$13) -> 1478400 | H24: =SUM('Total Fuel per Operation (Corn)'!N$10:N$13) -> 1920000 | I24: =SUM('Total Fuel per Operation (Corn)'!O$10:O$13) -> 9000000 | ... M24: =SUM('Total Fuel per Operation (Corn)'!S$10:S$13) -> 0 | N24: =SUM(B24:M24) -> 26976320 | O24: =$N24*AVERAGE('Assumptions&Calculations'!$B$3:$B$5) -> 1.8089421e+09 | P24: =$N24*AVERAGE('Assumptions&Calculations'!$M$3:$M$5) -> 7.0507751e+08
A25: Region II | B25: =SUM('Total Fuel per Operation (Corn)'!H$14:H$18) -> 3379584 | C25: =SUM('Total Fuel per Operation (Corn)'!I$14:I$18) -> 0 | D25: =SUM('Total Fuel per Operation (Corn)'!J$14:J$18) -> 0 | E25: =SUM('Total Fuel per Operation (Corn)'!K$14:K$18) -> 16008000 | F25: =SUM('Total Fuel per Operation (Corn)'!L$14:L$18) -> 0 | G25: =SUM('Total Fuel per Operation (Corn)'!M$14:M$18) -> 0 | H25: =SUM('Total Fuel per Operation (Corn)'!N$14:N$18) -> 3379584 | I25: =SUM('Total Fuel per Operation (Corn)'!O$14:O$18) -> 0 | ... M25: =SUM('Total Fuel per Operation (Corn)'!S$14:S$18) -> 0 | N25: =SUM(B25:M25) -> 38775168 | O25: =$N25*AVERAGE('Assumptions&Calculations'!$B$3:$B$5) -> 2.6001335e+09 | P25: =$N25*AVERAGE('Assumptions&Calculations'!$M$3:$M$5) -> 1.0134629e+09
A26: Region III | B26: =SUM('Total Fuel per Operation (Corn)'!H$19:H$25) -> 1202800 | C26: =SUM('Total Fuel per Operation (Corn)'!I$19:I$25) -> 0 | D26: =SUM('Total Fuel per Operation (Corn)'!J$19:J$25) -> 5366400 | E26: =SUM('Total Fuel per Operation (Corn)'!K$19:K$25) -> 470400 | F26: =SUM('Total Fuel per Operation (Corn)'!L$19:L$25) -> 0 | G26: =SUM('Total Fuel per Operation (Corn)'!M$19:M$25) -> 1006304 | H26: =SUM('Total Fuel per Operation (Corn)'!N$19:N$25) -> 196496 | I26: =SUM('Total Fuel per Operation (Corn)'!O$19:O$25) -> 0 | ... M26: =SUM('Total Fuel per Operation (Corn)'!S$19:S$25) -> 0 | N26: =SUM(B26:M26) -> 14079200 | O26: =$N26*AVERAGE('Assumptions&Calculations'!$B$3:$B$5) -> 9.4410422e+08 | P26: =$N26*AVERAGE('Assumptions&Calculations'!$M$3:$M$5) -> 3.6798671e+08
A27: CALABARZON | B27: =SUM('Total Fuel per Operation (Corn)'!H$26:H$30) -> 845760 | C27: =SUM('Total Fuel per Operation (Corn)'!I$26:I$30) -> 0 | D27: =SUM('Total Fuel per Operation (Corn)'!J$26:J$30) -> 0 | E27: =SUM('Total Fuel per Operation (Corn)'!K$26:K$30) -> 0 | F27: =SUM('Total Fuel per Operation (Corn)'!L$26:L$30) -> 2529600 | G27: =SUM('Total Fuel per Operation (Corn)'!M$26:M$30) -> 0 | H27: =SUM('Total Fuel per Operation (Corn)'!N$26:N$30) -> 0 | I27: =SUM('Total Fuel per Operation (Corn)'!O$26:O$30) -> 845760 | ... M27: =SUM('Total Fuel per Operation (Corn)'!S$26:S$30) -> 0 | N27: =SUM(B27:M27) -> 6750720 | O27: =$N27*AVERAGE('Assumptions&Calculations'!$B$3:$B$5) -> 4.5268078e+08 | P27: =$N27*AVERAGE('Assumptions&Calculations'!$M$3:$M$5) -> 1.7644293e+08
A28: MIMAROPA | B28: =SUM('Total Fuel per Operation (Corn)'!H$31:H$35) -> 0 | C28: =SUM('Total Fuel per Operation (Corn)'!I$31:I$35) -> 0 | D28: =SUM('Total Fuel per Operation (Corn)'!J$31:J$35) -> 0 | E28: =SUM('Total Fuel per Operation (Corn)'!K$31:K$35) -> 0 | F28: =SUM('Total Fuel per Operation (Corn)'!L$31:L$35) -> 2928000 | G28: =SUM('Total Fuel per Operation (Corn)'!M$31:M$35) -> 0 | H28: =SUM('Total Fuel per Operation (Corn)'!N$31:N$35) -> 0 | I28: =SUM('Total Fuel per Operation (Corn)'!O$31:O$35) -> 1363440 | ... M28: =SUM('Total Fuel per Operation (Corn)'!S$31:S$35) -> 1363440 | N28: =SUM(B28:M28) -> 8582880 | O28: =$N28*AVERAGE('Assumptions&Calculations'!$B$3:$B$5) -> 5.7553932e+08 | P28: =$N28*AVERAGE('Assumptions&Calculations'!$M$3:$M$5) -> 2.2432992e+08
A29: Region V | B29: =SUM('Total Fuel per Operation (Corn)'!H$36:H$41) -> 2510400 | C29: =SUM('Total Fuel per Operation (Corn)'!I$36:I$41) -> 0 | D29: =SUM('Total Fuel per Operation (Corn)'!J$36:J$41) -> 0 | E29: =SUM('Total Fuel per Operation (Corn)'!K$36:K$41) -> 1645872 | F29: =SUM('Total Fuel per Operation (Corn)'!L$36:L$41) -> 681600 | G29: =SUM('Total Fuel per Operation (Corn)'!M$36:M$41) -> 0 | H29: =SUM('Total Fuel per Operation (Corn)'!N$36:N$41) -> 1259472 | I29: =SUM('Total Fuel per Operation (Corn)'!O$36:O$41) -> 290400 | ... M29: =SUM('Total Fuel per Operation (Corn)'!S$36:S$41) -> 0 | N29: =SUM(B29:M29) -> 6387744 | O29: =$N29*AVERAGE('Assumptions&Calculations'!$B$3:$B$5) -> 4.2834082e+08 | P29: =$N29*AVERAGE('Assumptions&Calculations'!$M$3:$M$5) -> 1.6695586e+08
A30: Region VI | B30: =SUM('Total Fuel per Operation (Corn)'!H$42:H$46) -> 1404336 | C30: =SUM('Total Fuel per Operation (Corn)'!I$42:I$46) -> 0 | D30: =SUM('Total Fuel per Operation (Corn)'!J$42:J$46) -> 0 | E30: =SUM('Total Fuel per Operation (Corn)'!K$42:K$46) -> 1291200 | F30: =SUM('Total Fuel per Operation (Corn)'!L$42:L$46) -> 0 | G30: =SUM('Total Fuel per Operation (Corn)'!M$42:M$46) -> 0 | H30: =SUM('Total Fuel per Operation (Corn)'!N$42:N$46) -> 1404336 | I30: =SUM('Total Fuel per Operation (Corn)'!O$42:O$46) -> 0 | ... M30: =SUM('Total Fuel per Operation (Corn)'!S$42:S$46) -> 0 | N30: =SUM(B30:M30) -> 5391072 | O30: =$N30*AVERAGE('Assumptions&Calculations'!$B$3:$B$5) -> 3.6150732e+08 | P30: =$N30*AVERAGE('Assumptions&Calculations'!$M$3:$M$5) -> 1.4090594e+08
A31: NIR | B31: =SUM('Total Fuel per Operation (Corn)'!H$47:H$49) -> 400352 | C31: =SUM('Total Fuel per Operation (Corn)'!I$47:I$49) -> 0 | D31: =SUM('Total Fuel per Operation (Corn)'!J$47:J$49) -> 0 | E31: =SUM('Total Fuel per Operation (Corn)'!K$47:K$49) -> 705600 | F31: =SUM('Total Fuel per Operation (Corn)'!L$47:L$49) -> 0 | G31: =SUM('Total Fuel per Operation (Corn)'!M$47:M$49) -> 0 | H31: =SUM('Total Fuel per Operation (Corn)'!N$47:N$49) -> 400352 | I31: =SUM('Total Fuel per Operation (Corn)'!O$47:O$49) -> 0 | ... M31: =SUM('Total Fuel per Operation (Corn)'!S$47:S$49) -> 0 | N31: =SUM(B31:M31) -> 2211904 | O31: =$N31*AVERAGE('Assumptions&Calculations'!$B$3:$B$5) -> 1.4832291e+08 | P31: =$N31*AVERAGE('Assumptions&Calculations'!$M$3:$M$5) -> 57812324
A32: Region VII | B32: =SUM('Total Fuel per Operation (Corn)'!H$50:H$51) -> 0 | C32: =SUM('Total Fuel per Operation (Corn)'!I$50:I$51) -> 0 | D32: =SUM('Total Fuel per Operation (Corn)'!J$50:J$51) -> 0 | E32: =SUM('Total Fuel per Operation (Corn)'!K$50:K$51) -> 912000 | F32: =SUM('Total Fuel per Operation (Corn)'!L$50:L$51) -> 0 | G32: =SUM('Total Fuel per Operation (Corn)'!M$50:M$51) -> 0 | H32: =SUM('Total Fuel per Operation (Corn)'!N$50:N$51) -> 391520 | I32: =SUM('Total Fuel per Operation (Corn)'!O$50:O$51) -> 0 | ... M32: =SUM('Total Fuel per Operation (Corn)'!S$50:S$51) -> 391520 | N32: =SUM(B32:M32) -> 2607040 | O32: =$N32*AVERAGE('Assumptions&Calculations'!$B$3:$B$5) -> 1.7481941e+08 | P32: =$N32*AVERAGE('Assumptions&Calculations'!$M$3:$M$5) -> 68139956
A33: Region VIII | B33: =SUM('Total Fuel per Operation (Corn)'!H$52:H$57) -> 488304 | C33: =SUM('Total Fuel per Operation (Corn)'!I$52:I$57) -> 0 | D33: =SUM('Total Fuel per Operation (Corn)'!J$52:J$57) -> 0 | E33: =SUM('Total Fuel per Operation (Corn)'!K$52:K$57) -> 1051200 | F33: =SUM('Total Fuel per Operation (Corn)'!L$52:L$57) -> 0 | G33: =SUM('Total Fuel per Operation (Corn)'!M$52:M$57) -> 0 | H33: =SUM('Total Fuel per Operation (Corn)'!N$52:N$57) -> 488304 | I33: =SUM('Total Fuel per Operation (Corn)'!O$52:O$57) -> 0 | ... M33: =SUM('Total Fuel per Operation (Corn)'!S$52:S$57) -> 0 | N33: =SUM(B33:M33) -> 3079008 | O33: =$N33*AVERAGE('Assumptions&Calculations'!$B$3:$B$5) -> 2.0646801e+08 | P33: =$N33*AVERAGE('Assumptions&Calculations'!$M$3:$M$5) -> 80475739
A34: Region IX | B34: =SUM('Total Fuel per Operation (Corn)'!H$58:H$60) -> 0 | C34: =SUM('Total Fuel per Operation (Corn)'!I$58:I$60) -> 1051200 | D34: =SUM('Total Fuel per Operation (Corn)'!J$58:J$60) -> 211200 | E34: =SUM('Total Fuel per Operation (Corn)'!K$58:K$60) -> 0 | F34: =SUM('Total Fuel per Operation (Corn)'!L$58:L$60) -> 792432 | G34: =SUM('Total Fuel per Operation (Corn)'!M$58:M$60) -> 96576 | H34: =SUM('Total Fuel per Operation (Corn)'!N$58:N$60) -> 0 | I34: =SUM('Total Fuel per Operation (Corn)'!O$58:O$60) -> 1051200 | ... M34: =SUM('Total Fuel per Operation (Corn)'!S$58:S$60) -> 96576 | N34: =SUM(B34:M34) -> 4302816 | O34: =$N34*AVERAGE('Assumptions&Calculations'!$B$3:$B$5) -> 2.885325e+08 | P34: =$N34*AVERAGE('Assumptions&Calculations'!$M$3:$M$5) -> 1.1246229e+08
A35: Region X | B35: =SUM('Total Fuel per Operation (Corn)'!H$61:H$65) -> 1266560 | C35: =SUM('Total Fuel per Operation (Corn)'!I$61:I$65) -> 6413648 | D35: =SUM('Total Fuel per Operation (Corn)'!J$61:J$65) -> 0 | E35: =SUM('Total Fuel per Operation (Corn)'!K$61:K$65) -> 0 | F35: =SUM('Total Fuel per Operation (Corn)'!L$61:L$65) -> 2501008 | G35: =SUM('Total Fuel per Operation (Corn)'!M$61:M$65) -> 0 | H35: =SUM('Total Fuel per Operation (Corn)'!N$61:N$65) -> 0 | I35: =SUM('Total Fuel per Operation (Corn)'!O$61:O$65) -> 0 | ... M35: =SUM('Total Fuel per Operation (Corn)'!S$61:S$65) -> 0 | N35: =SUM(B35:M35) -> 15360416 | O35: =$N35*AVERAGE('Assumptions&Calculations'!$B$3:$B$5) -> 1.0300183e+09 | P35: =$N35*AVERAGE('Assumptions&Calculations'!$M$3:$M$5) -> 4.0147373e+08
A36: Region XI | B36: =SUM('Total Fuel per Operation (Corn)'!H$66:H$70) -> 1756800 | C36: =SUM('Total Fuel per Operation (Corn)'!I$66:I$70) -> 0 | D36: =SUM('Total Fuel per Operation (Corn)'!J$66:J$70) -> 0 | E36: =SUM('Total Fuel per Operation (Corn)'!K$66:K$70) -> 895616 | F36: =SUM('Total Fuel per Operation (Corn)'!L$66:L$70) -> 0 | G36: =SUM('Total Fuel per Operation (Corn)'!M$66:M$70) -> 0 | H36: =SUM('Total Fuel per Operation (Corn)'!N$66:N$70) -> 1756800 | I36: =SUM('Total Fuel per Operation (Corn)'!O$66:O$70) -> 0 | ... M36: =SUM('Total Fuel per Operation (Corn)'!S$66:S$70) -> 0 | N36: =SUM(B36:M36) -> 5304832 | O36: =$N36*AVERAGE('Assumptions&Calculations'!$B$3:$B$5) -> 3.5572435e+08 | P36: =$N36*AVERAGE('Assumptions&Calculations'!$M$3:$M$5) -> 1.3865189e+08
A37: Region XII | B37: =SUM('Total Fuel per Operation (Corn)'!H$71:H$74) -> 0 | C37: =SUM('Total Fuel per Operation (Corn)'!I$71:I$74) -> 0 | D37: =SUM('Total Fuel per Operation (Corn)'!J$71:J$74) -> 0 | E37: =SUM('Total Fuel per Operation (Corn)'!K$71:K$74) -> 4219200 | F37: =SUM('Total Fuel per Operation (Corn)'!L$71:L$74) -> 0 | G37: =SUM('Total Fuel per Operation (Corn)'!M$71:M$74) -> 0 | H37: =SUM('Total Fuel per Operation (Corn)'!N$71:N$74) -> 2405584 | I37: =SUM('Total Fuel per Operation (Corn)'!O$71:O$74) -> 0 | ... M37: =SUM('Total Fuel per Operation (Corn)'!S$71:S$74) -> 2405584 | N37: =SUM(B37:M37) -> 13249568 | O37: =$N37*AVERAGE('Assumptions&Calculations'!$B$3:$B$5) -> 8.8847186e+08 | P37: =$N37*AVERAGE('Assumptions&Calculations'!$M$3:$M$5) -> 3.463027e+08
A38: Region XIII | B38: =SUM('Total Fuel per Operation (Corn)'!H$75:H$79) -> 0 | C38: =SUM('Total Fuel per Operation (Corn)'!I$75:I$79) -> 763456 | D38: =SUM('Total Fuel per Operation (Corn)'!J$75:J$79) -> 0 | E38: =SUM('Total Fuel per Operation (Corn)'!K$75:K$79) -> 0 | F38: =SUM('Total Fuel per Operation (Corn)'!L$75:L$79) -> 2112000 | G38: =SUM('Total Fuel per Operation (Corn)'!M$75:M$79) -> 0 | H38: =SUM('Total Fuel per Operation (Corn)'!N$75:N$79) -> 0 | I38: =SUM('Total Fuel per Operation (Corn)'!O$75:O$79) -> 763456 | ... M38: =SUM('Total Fuel per Operation (Corn)'!S$75:S$79) -> 0 | N38: =SUM(B38:M38) -> 5750912 | O38: =$N38*AVERAGE('Assumptions&Calculations'!$B$3:$B$5) -> 3.8563699e+08 | P38: =$N38*AVERAGE('Assumptions&Calculations'!$M$3:$M$5) -> 1.5031104e+08
A39: BARMM | B39: =SUM('Total Fuel per Operation (Corn)'!H$80:H$82) -> 0 | C39: =SUM('Total Fuel per Operation (Corn)'!I$80:I$82) -> 0 | D39: =SUM('Total Fuel per Operation (Corn)'!J$80:J$82) -> 120000 | E39: =SUM('Total Fuel per Operation (Corn)'!K$80:K$82) -> 31152 | F39: =SUM('Total Fuel per Operation (Corn)'!L$80:L$82) -> 0 | G39: =SUM('Total Fuel per Operation (Corn)'!M$80:M$82) -> 0 | H39: =SUM('Total Fuel per Operation (Corn)'!N$80:N$82) -> 120000 | I39: =SUM('Total Fuel per Operation (Corn)'!O$80:O$82) -> 0 | ... M39: =SUM('Total Fuel per Operation (Corn)'!S$80:S$82) -> 151152 | N39: =SUM(B39:M39) -> 453456 | O39: =$N39*AVERAGE('Assumptions&Calculations'!$B$3:$B$5) -> 30407248 | P39: =$N39*AVERAGE('Assumptions&Calculations'!$M$3:$M$5) -> 11851936
A40: Total per Month | B40: =SUM(B23:B39) -> 13881808 | C40: =SUM(C23:C39) -> 21939136 | D40: =SUM(D23:D39) -> 5697600 | E40: =SUM(E23:E39) -> 28545440 | F40: =SUM(F23:F39) -> 13038672 | G40: =SUM(G23:G39) -> 2581280 | H40: =SUM(H23:H39) -> 14883120 | I40: =SUM(I23:I39) -> 13314256 | ... N40: =SUM(N23:N39) -> 165772144 | O40: =N40*AVERAGE('Assumptions&Calculations'!$B$3:$B$5) -> 1.1116127e+10 | P40: =$N40*AVERAGE('Assumptions&Calculations'!$M$3:$M$5) -> 4.3327707e+09
A42: HVC | B42: January | C42: February | D42: March | E42: April | F42: May | G42: June | H42: July | I42: August | J42: September | K42: October | L42: November | M42: December | N42: Total Fuel (L) Per Region | O42: Cost (Php) Per Region @ average fuel cost | P42: Cost (Php) Per Region @ incremental cost
...

Sheet L Requirements
A1: Region | B1: Rice | C1: Corn | D1: HVC | E1: Sugar | F1: Total
A2: CAR | B2: =Summary!N3 -> 2007985.6 | C2: =Summary!N23 -> 6509088 | D2: =Summary!N43 -> 1158637 | E2: =Summary!N63 -> 0 | F2: =SUM(B2:E2) -> 9675710.6 | G2: =F2*60 -> 580542636 | I2: =D2+E2 -> 1158637
A3: Region I | B3: =Summary!N4 -> 33623794 | C3: =Summary!N24 -> 26976320 | D3: =Summary!N44 -> 2098144 | E3: =Summary!N64 -> 0 | F3: =SUM(B3:E3) -> 62698258 | G3: =F3*60 -> 3761895456 | I3: =D3+E3 -> 2098144
A4: Region II | B4: =Summary!N5 -> 54953507 | C4: =Summary!N25 -> 38775168 | D4: =Summary!N45 -> 17560568 | E4: =Summary!N65 -> 380539.67 | F4: =SUM(B4:E4) -> 1.1166978e+08 | G4: =F4*60 -> 6.700187e+09 | I4: =D4+E4 -> 17941108
A5: Region III | B5: =Summary!N6 -> 33191945 | C5: =Summary!N26 -> 14079200 | D5: =Summary!N46 -> 2759300 | E5: =Summary!N66 -> 857201.92 | F5: =SUM(B5:E5) -> 50887647 | G5: =F5*60 -> 3.0532588e+09 | I5: =D5+E5 -> 3616501.9
A6: CALABARZON | B6: =Summary!N7 -> 11080654 | C6: =Summary!N27 -> 6750720 | D6: =Summary!N47 -> 5339848 | E6: =Summary!N67 -> 2498327.8 | F6: =SUM(B6:E6) -> 25669550 | G6: =F6*60 -> 1.540173e+09 | I6: =D6+E6 -> 7838175.8
A7: MIMAROPA | B7: =Summary!N8 -> 10699891 | C7: =Summary!N28 -> 8582880 | D7: =Summary!N48 -> 538070 | E7: =Summary!N68 -> 0 | F7: =SUM(B7:E7) -> 19820841 | G7: =F7*60 -> 1.1892505e+09 | I7: =D7+E7 -> 538070
A8: Region V | B8: =Summary!N9 -> 13271970 | C8: =Summary!N29 -> 6387744 | D8: =Summary!N49 -> 1902227 | E8: =Summary!N69 -> 257740.48 | F8: =SUM(B8:E8) -> 21819681 | G8: =F8*60 -> 1.3091809e+09 | I8: =D8+E8 -> 2159967.5
A9: Region VI | B9: =Summary!N10 -> 8189092.8 | C9: =Summary!N30 -> 5391072 | D9: =Summary!N50 -> 578794 | E9: =Summary!N70 -> 3585124 | F9: =SUM(B9:E9) -> 17744083 | G9: =F9*60 -> 1064644968 | I9: =D9+E9 -> 4163918
A10: NIR | B10: =Summary!N11 -> 2220524.8 | C10: =Summary!N31 -> 2211904 | D10: =Summary!N51 -> 1316248 | E10: =Summary!N71 -> 30914745 | F10: =SUM(B10:E10) -> 36663422 | G10: =F10*60 -> 2199805326 | I10: =D10+E10 -> 32230993
A11: Region VII | B11: =Summary!N12 -> 2920065.6 | C11: =Summary!N32 -> 2607040 | D11: =Summary!N52 -> 698126 | E11: =Summary!N72 -> 388785.1 | F11: =SUM(B11:E11) -> 6614016.7 | G11: =F11*60 -> 3.96841e+08 | I11: =D11+E11 -> 1086911.1
A12: Region VIII | B12: =Summary!N13 -> 7199756.8 | C12: =Summary!N33 -> 3079008 | D12: =Summary!N53 -> 1905056 | E12: =Summary!N73 -> 627153.88 | F12: =SUM(B12:E12) -> 12810975 | G12: =F12*60 -> 7.6865848e+08 | I12: =D12+E12 -> 2532209.9
A13: Region IX | B13: =Summary!N14 -> 4640419.2 | C13: =Summary!N34 -> 4302816 | D13: =Summary!N54 -> 676647 | E13: =Summary!N74 -> 0 | F13: =SUM(B13:E13) -> 9619882.2 | G13: =F13*60 -> 577192932 | I13: =D13+E13 -> 676647
... A17: Region XIII | B17: =Summary!N18 -> 15741677 | C17: =Summary!N38 -> 5750912 | D17: =Summary!N58 -> 6089918 | E17: =Summary!N78 -> 0 | F17: =SUM(B17:E17) -> 27582507 | G17: =F17*60 -> 1654950408 | I17: =D17+E17 -> 6089918
A18: BARMM | B18: =Summary!N19 -> 157520 | C18: =Summary!N39 -> 453456 | D18: =Summary!N59 -> 26420 | E18: =Summary!N79 -> 0 | F18: =SUM(B18:E18) -> 637396 | G18: =F18*60 -> 38243760 | H18: =F18/F19 -> 0.0012619275 | I18: =D18+E18 -> 26420
A19: Total | B19: =SUM(B2:B18) -> 237948411 | C19: =SUM(C2:C18) -> 165772144 | D19: =SUM(D2:D18) -> 52123657 | E19: =SUM(E2:E18) -> 49252955 | F19: =SUM(F2:F18) -> 5.0509717e+08 | G19: =F19*60 -> 3.030583e+10 | I19: =D19+E19 -> 1.0137661e+08
B20: =B19*60 -> 14276904660 | C20: =C19*60 -> 9946328640 | D20: =D19*60 -> 3127419420 | E20: =E19*60 -> 2.9551773e+09 | F20: =F19*60 -> 3.030583e+10

Sheet Beneficiary Estimation
A1: FUEL COST PER REGION (Php) | O1: Target No of Beneficiaries | U1: Financial Allocation | W1: Administrative Fund | Y1: Total Fund Allocation | AA1: Target No of Beneficiaries | AG1: Financial Allocation | AN1: Administrative Fund | AU1: Total Regional Fund (Program and Administrative) | AV1: Percentage Share | AW1: Total Fund Allocation | AY1: Total Number of Beneficiaries | AZ1: Total Percentage Share | BA1: 2022 | BG1: Increment | BH1: Percentage Increment
A2: REGION | B2: RICE | D2: CORN | F2: HVC | H2: SUGAR | J2: CROPS | L2: FISHERIES | O2: CROPS | R2: FISHERIES | AA2: CROPS | AD2: FISHERIES | BA2: Number of Beneficiaries | BC2: Total Fuel Fund
B3: 100% Subsidy | C3: incremental Cost | D3: 100% Subsidy | E3: incremental Cost | F3: 100% Subsidy | G3: incremental Cost | H3: 100% Subsidy | I3: incremental Cost | J3: 100% Subsidy | K3: incremental Cost | L3: Marine Capture | M3: Aquaculture | N3: Total Cost | O3: Percentage Share | P3: Number of Beneficiaries | Q3: Round | R3: Percentage Share | S3: Number of Beneficiaries | T3: Round | U3: Crop | V3: Fisheries | W3: Crop | X3: Fisheries | Y3: Crop | Z3: Fisheries | AA3: Percentage Share | AB3: Number of Beneficiaries | AC3: Round | AD3: Percentage Share | AE3: Number of Beneficiaries | AF3: Round | AG3: Crop | AJ3: Fisheries | AL3: Total | AM3: Total ('000) | AN3: Percentage Share | AO3: Crop | AQ3: Fisheries | AS3: Total | AT3: Total ('000) | AW3: Crop | AX3: Fisheries | BA3: Crops (Corn) | BB3: Fisheries | BC3: Crops (Corn) | BD3: Fisheries | BE3: Total | BF3: Percentage Share
A4: NCR | L4: =Summary!O83 -> 7.6468604e+09 | M4: =Summary!O104 -> 1.3782781e+08 | N4: =SUM(L4:M4) -> 7.7846882e+09 | O4: =K4/$K$21 -> 0 | P4: =$J$31*O4 -> 0 | Q4: =ROUND(P4, 0) -> 0 | R4: =N4/$N$21 -> 0.091436985 | S4: =R4*$J$32 -> 8818.3603 | T4: =ROUND(S4,0) -> 8818 | U4: =Q4*$I$30 -> 0 | V4: =S4*$I$30 -> 44091802 | W4: =Y4-U4 -> 0 | X4: =Z4-V4 -> 671448.76 | Y4: =Q4*$I$30/0.985 -> 0 | Z4: =S4*$I$30/0.985 -> 44763250 | AA4: =J4/$J$21 -> 0 | AB4: =$M$31*AA4 -> 0 | AC4: =ROUND(AB4, 0) -> 0 | AD4: =N4/$N$21 -> 0.091436985 | AE4: =AD4*$M$32 -> 8561.5149 | AF4: =ROUND(AE4,0)+1 -> 8563 | AG4: =AB4*$L$30 -> 0 | AH4: =ROUND(AG4,0) -> 0 | AI4: =AC4*$L$30 -> 0 | AJ4: =AE4*$L$30 -> 44091802 | AK4: =AF4*$L$30 -> 44099450 | AL4: =AG4+AJ4 -> 44091802 | AM4: =ROUND(AL4/1000,2) -> 44091.8 | AN4: =AL4/$AW$23 -> 0.044091802 | AO4: =(AW4-AG4)*$AQ$24 -> 0 | AP4: =ROUND(AO4,0) -> 0 | AQ4: =(AX4-AJ4)*$AQ$24 -> 637876.32 | AR4: =ROUND(AQ4,0) -> 637876 | AS4: =SUM(AO4:AQ4) -> 637876.32 | AT4: =ROUND(AS4/1000,2) -> 637.88 | AU4: =AQ4+AL4+AO4 -> 44729678 | AV4: =AU4/$AW$23 -> 0.044729678 | AW4: =AB4*$L$30/0.985 -> 0 | AX4: =AE4*$L$30/0.985 -> 44763250 | AY4: =AC4+AF4 -> 8563 | AZ4: =AY4/$AY$21 -> 0.044770345 | BA4: 2124 | BC4: =BA4*3150 -> 6690600 | BD4: =BB4*3150 -> 0 | BE4: =SUM(BC4:BD4) -> 6690600 | BF4: =BE4/$BE$21 -> 0.013381213 | BG4: =AU4-BE4 -> 38039078 | BH4: =BG4/BE4 -> 5.6854509
A5: CAR | B5: =Summary!O3 -> 1.3464882e+08 | C5: 42187777 | D5: =Summary!O23 -> 4.3647774e+08 | E5: 44734828 | F5: =Summary!O43 -> 77694335 | G5: 7967538.3 | H5: =Summary!O63 -> 0 | I5: 0 | J5: =B5+D5+F5+H5 -> 6.488209e+08 | K5: =C5+E5+G5+I5 -> 94890144 | L5: =Summary!O84 -> 50665872 | M5: =Summary!O105 -> 61171774 | N5: =SUM(L5:M5) -> 1.1183765e+08 | O5: =K5/$K$21 -> 0.017546755 | P5: =$J$31*O5 -> 1764.4677 | Q5: =ROUND(P5, 0) -> 1764 | R5: =N5/$N$21 -> 0.0013136168 | S5: =R5*$J$32 -> 126.68775 | T5: =ROUND(S5,0) -> 127 | U5: =Q5*$I$30 -> 8820000 | V5: =S5*$I$30 -> 633438.77 | W5: =Y5-U5 -> 134314.72 | X5: =Z5-V5 -> 9646.2756 | Y5: =Q5*$I$30/0.985 -> 8954314.7 | Z5: =S5*$I$30/0.985 -> 643085.04 | AA5: =J5/$J$21 -> 0.020655452 | AB5: =$M$31*AA5 -> 2016.5749 | AC5: =ROUND(AB5, 0) -> 2017 | AD5: =N5/$N$21 -> 0.0013136168 | AE5: =AD5*$M$32 -> 122.99782 | AF5: =ROUND(AE5,0) -> 123 | AG5: =AB5*$L$30 -> 10385361 | AH5: =ROUND(AG5,0) -> 10385361 | AI5: =AC5*$L$30 -> 10387550 | AJ5: =AE5*$L$30 -> 633438.77 | AK5: =AF5*$L$30 -> 633450 | AL5: =AG5+AJ5 -> 11018799 | AM5: =ROUND(AL5/1000,2) -> 11018.8 | AN5: =AL5/$AW$23 -> 0.011018799 | AO5: =(AW5-AG5)*$AQ$24 -> 150245.07 | AP5: =ROUND(AO5,0) -> 150245 | AQ5: =(AX5-AJ5)*$AQ$24 -> 9163.9618 | AR5: =ROUND(AQ5,0) -> 9164 | AS5: =SUM(AO5:AQ5) -> 309654.03 | AT5: =ROUND(AS5/1000,2) -> 309.65 | AU5: =AQ5+AL5+AO5 -> 11178208 | AV5: =AU5/$AW$23 -> 0.011178208 | AW5: =AB5*$L$30/0.985 -> 10543513 | AX5: =AE5*$L$30/0.985 -> 643085.04 | AY5: =AC5+AF5 -> 2140 | AZ5: =AY5/$AY$21 -> 0.011188665 | BA5: 308 | BB5: 1502 | BC5: =BA5*3150 -> 970200 | BD5: =BB5*3150 -> 4731300 | BE5: =SUM(BC5:BD5) -> 5701500 | BF5: =BE5/$BE$21 -> 0.011403011 | BG5: =AU5-BE5 -> 5476708.4 | BH5: =BG5/BE5 -> 0.96057326
A6: Region I | B6: =Summary!O4 -> 2.2546995e+09 | C6: 2.3149211e+08 | D6: =Summary!O24 -> 1.8089421e+09 | E6: 1.8591463e+08 | F6: =Summary!O44 -> 1.4069454e+08 | G6: 14470301 | H6: =Summary!O64 -> 0 | I6: 0 | J6: =B6+D6+F6+H6 -> 4.2043362e+09 | K6: =C6+E6+G6+I6 -> 4.3187705e+08 | L6: =Summary!O85 -> 4.9169577e+09 | M6: =Summary!O106 -> 1.4567165e+08 | N6: =SUM(L6:M6) -> 5.0626294e+09 | O6: =K6/$K$21 -> 0.079861202 | P6: =$J$31*O6 -> 8030.6874 | Q6: =ROUND(P6, 0) -> 8031 | R6: =N6/$N$21 -> 0.059464369 | S6: =R6*$J$32 -> 5734.8591 | T6: =ROUND(S6,0) -> 5735 | U6: =Q6*$I$30 -> 40155000 | V6: =S6*$I$30 -> 28674296 | W6: =Y6-U6 -> 611497.46 | X6: =Z6-V6 -> 436664.4 | Y6: =Q6*$I$30/0.985 -> 40766497 | Z6: =S6*$I$30/0.985 -> 29110960 | AA6: =J6/$J$21 -> 0.13384659 | AB6: =$M$31*AA6 -> 13067.333 | AC6: =ROUND(AB6, 0) -> 13067 | AD6: =N6/$N$21 -> 0.059464369 | AE6: =AD6*$M$32 -> 5567.8244 | AF6: =ROUND(AE6,0) -> 5568 | AG6: =AB6*$L$30 -> 67296764 | AH6: =ROUND(AG6,0) -> 67296764 | AI6: =AC6*$L$30 -> 67295050 | AJ6: =AE6*$L$30 -> 28674296 | AK6: =AF6*$L$30 -> 28675200 | AL6: =AG6+AJ6 -> 95971060 | AM6: =ROUND(AL6/1000,2) -> 95971.06 | AN6: =AL6/$AW$23 -> 0.09597106 | AO6: =(AW6-AG6)*$AQ$24 -> 973582.63 | AP6: =ROUND(AO6,0) -> 973583 | AQ6: =(AX6-AJ6)*$AQ$24 -> 414831.18 | AR6: =ROUND(AQ6,0) -> 414831 | AS6: =SUM(AO6:AQ6) -> 2361996.8 | AT6: =ROUND(AS6/1000,2) -> 2362 | AU6: =AQ6+AL6+AO6 -> 97359474 | AV6: =AU6/$AW$23 -> 0.097359474 | AW6: =AB6*$L$30/0.985 -> 68321588 | AX6: =AE6*$L$30/0.985 -> 29110960 | AY6: =AC6+AF6 -> 18635 | AZ6: =AY6/$AY$21 -> 0.097430267 | BA6: 5097 | BB6: 12244 | BC6: =BA6*3150 -> 16055550 | BD6: =BB6*3150 -> 38568600 | BE6: =SUM(BC6:BD6) -> 54624150 | BF6: =BE6/$BE$21 -> 0.10924841 | BG6: =AU6-BE6 -> 42735324 | BH6: =BG6/BE6 -> 0.7823522
A7: Region II | B7: =Summary!O5 -> 3.684999e+09 | C7: 3.7852133e+08 | D7: =Summary!O25 -> 2.6001335e+09 | E7: 2.6693659e+08 | F7: =Summary!O45 -> 1.1775532e+09 | G7: 1.2094028e+08 | H7: =Summary!O65 -> 25517722 | I7: 7995138.5 | J7: =B7+D7+F7+H7 -> 7.4882034e+09 | K7: =C7+E7+G7+I7 -> 7.7439334e+08 | L7: =Summary!O86 -> 1.555844e+09 | M7: =Summary!O107 -> 4.7154409e+08 | N7: =SUM(L7:M7) -> 2.027388e+09 | O7: =K7/$K$21 -> 0.14319812 | P7: =$J$31*O7 -> 14399.725 | Q7: =ROUND(P7, 0) -> 14400 | R7: =N7/$N$21 -> 0.023813189 | S7: =R7*$J$32 -> 2296.5902 | T7: =ROUND(S7,0) -> 2297 | U7: =Q7*$I$30 -> 72000000 | V7: =S7*$I$30 -> 11482951 | W7: =Y7-U7 -> 1096446.7 | X7: =Z7-V7 -> 174867.27 | Y7: =Q7*$I$30/0.985 -> 73096447 | Z7: =S7*$I$30/0.985 -> 11657818 | AA7: =J7/$J$21 -> 0.23838971 | AB7: =$M$31*AA7 -> 23273.792 | AC7: =ROUND(AB7, 0) -> 23274 | AD7: =N7/$N$21 -> 0.023813189 | AE7: =AD7*$M$32 -> 2229.6992 | AF7: =ROUND(AE7,0) -> 2230 | AG7: =AB7*$L$30 -> 1.1986003e+08 | AH7: =ROUND(AG7,0) -> 119860031 | AI7: =AC7*$L$30 -> 119861100 | AJ7: =AE7*$L$30 -> 11482951 | AK7: =AF7*$L$30 -> 11484500 | AL7: =AG7+AJ7 -> 1.3134298e+08 | AM7: =ROUND(AL7/1000,2) -> 131342.98 | AN7: =AL7/$AW$23 -> 0.13134298 | AO7: =(AW7-AG7)*$AQ$24 -> 1734015.7 | AP7: =ROUND(AO7,0)+1 -> 1734017 | AQ7: =(AX7-AJ7)*$AQ$24 -> 166123.91 | AR7: =ROUND(AQ7,0)+1 -> 166125 | AS7: =SUM(AO7:AQ7) -> 3634156.6 | AT7: =ROUND(AS7/1000,2) -> 3634.16 | AU7: =AQ7+AL7+AO7 -> 1.3324312e+08 | AV7: =AU7/$AW$23 -> 0.13324312 | AW7: =AB7*$L$30/0.985 -> 1.2168531e+08 | AX7: =AE7*$L$30/0.985 -> 11657818 | AY7: =AC7+AF7 -> 25504 | AZ7: =AY7/$AY$21 -> 0.13334379 | BA7: 2303 | BB7: 16811 | BC7: =BA7*3150 -> 7254450 | BD7: =BB7*3150 -> 52954650 | BE7: =SUM(BC7:BD7) -> 60209100 | BF7: =BE7/$BE$21 -> 0.12041832 | BG7: =AU7-BE7 -> 73034021 | BH7: =BG7/BE7 -> 1.2130064
A8: Region III | B8: =Summary!O6 -> 2.2257412e+09 | C8: 6.309502e+08 | D8: =Summary!O26 -> 9.4410422e+08 | E8: 2.6721089e+08 | F8: =Summary!O46 -> 1.8502946e+08 | G8: 52326329 | H8: =Summary!O66 -> 57481103 | I8: 18009812 | J8: =B8+D8+F8+H8 -> 3.412356e+09 | K8: =C8+E8+G8+I8 -> 9.6849724e+08 | L8: =Summary!O87 -> 3.0758225e+09 | M8: =Summary!O108 -> 496004.75 | N8: =SUM(L8:M8) -> 3.0763185e+09 | O8: =K8/$K$21 -> 0.17909114 | P8: =$J$31*O8 -> 18009.058 | Q8: =ROUND(P8, 0) -> 18009 | R8: =N8/$N$21 -> 0.036133662 | S8: =R8*$J$32 -> 3484.8005 | T8: =ROUND(S8,0) -> 3485 | U8: =Q8*$I$30 -> 90045000 | V8: =S8*$I$30 -> 17424002 | W8: =Y8-U8 -> 1371243.7 | X8: =Z8-V8 -> 265340.14 | Y8: =Q8*$I$30/0.985 -> 91416244 | Z8: =S8*$I$30/0.985 -> 17689343 | AA8: =J8/$J$21 -> 0.10863361 | AB8: =$M$31*AA8 -> 10605.81 | AC8: =ROUND(AB8, 0) -> 10606 | AD8: =N8/$N$21 -> 0.036133662 | AE8: =AD8*$M$32 -> 3383.3015 | AF8: =ROUND(AE8,0) -> 3383 | AG8: =AB8*$L$30 -> 54619923 | AH8: =ROUND(AG8,0) -> 54619923 | AI8: =AC8*$L$30 -> 54620900 | AJ8: =AE8*$L$30 -> 17424002 | AK8: =AF8*$L$30 -> 17422450 | AL8: =AG8+AJ8 -> 72043925 | AM8: =ROUND(AL8/1000,2) -> 72043.93 | AN8: =AL8/$AW$23 -> 0.072043925 | AO8: =(AW8-AG8)*$AQ$24 -> 790186.7 | AP8: =ROUND(AO8,0) -> 790187 | AQ8: =(AX8-AJ8)*$AQ$24 -> 252073.13 | AR8: =ROUND(AQ8,0) -> 252073 | AS8: =SUM(AO8:AQ8) -> 1832446.8 | AT8: =ROUND(AS8/1000,2) -> 1832.45 | AU8: =AQ8+AL8+AO8 -> 73086185 | AV8: =AU8/$AW$23 -> 0.073086185 | AW8: =AB8*$L$30/0.985 -> 55451698 | AX8: =AE8*$L$30/0.985 -> 17689343 | AY8: =AC8+AF8 -> 13989 | AZ8: =AY8/$AY$21 -> 0.073139362 | BA8: 7049 | BB8: 2255 | BC8: =BA8*3150 -> 22204350 | BD8: =BB8*3150 -> 7103250 | BE8: =SUM(BC8:BD8) -> 29307600 | BF8: =BE8/$BE$21 -> 0.058615259 | BG8: =AU8-BE8 -> 43778585 | BH8: =BG8/BE8 -> 1.4937622
